Workbook

Sheet box office
A1: Year | B1: Total Gross | C1: %± LY | D1: Releases | E1: Average | F1: #1 Release | I1: Source: https://www.boxofficemojo.com/year/?sort=year&ref_=bo_yl__resort#table
A2: 2025 | B2: 5190781672 | C2: - | D2: 394 | E2: 13174572 | F2: A Minecraft Movie
A3: 2024 | B3: 8570012657 | C3: -0.038 | D3: 675 | E3: 12696315 | F3: Inside Out 2
A4: 2023 | B4: 8907111984 | C4: 0.209 | D4: 592 | E4: 15045797 | F4: Barbie
A5: 2022 | B5: 7369914732 | C5: 0.644 | D5: 502 | E5: 14681105 | F5: Top Gun: Maverick
A6: 2021 | B6: 4483016589 | C6: 1.121 | D6: 442 | E6: 10142571 | F6: Spider-Man: No Way Home
A7: 2020 | B7: 2113386800 | C7: -0.814 | D7: 455 | E7: 4644806 | F7: Bad Boys for Life
A8: 2019 | B8: 11363364803 | C8: -0.044 | D8: 910 | E8: 12487214 | F8: Avengers: Endgame
A9: 2018 | B9: 11892160011 | C9: 0.074 | D9: 993 | E9: 11975991 | F9: Black Panther
A10: 2017 | B10: 11075387520 | C10: -0.026 | D10: 854 | E10: 12968837 | F10: Star Wars: Episode VIII - The Last Jedi
A11: 2016 | B11: 11375225455 | C11: 0.02 | D11: 855 | E11: 13304357 | F11: Finding Dory
A12: 2015 | B12: 11148780747 | C12: 0.075 | D12: 845 | E12: 13193823 | F12: Jurassic World
A13: 2014 | B13: 10368861849 | C13: -0.054 | D13: 849 | E13: 12213029 | F13: Guardians of the Galaxy
A14: 2013 | B14: 10955524800 | C14: 0.01 | D14: 826 | E14: 13263347 | F14: Iron Man 3
... A50: 1977 | B50: 443497461 | C50: 2.906 | D50: 9 | E50: 49277495 | F50: Star Wars: Episode IV - A New Hope

Sheet combined
A1: Year | B1: Tickets Sold | C1: Total Box Office | D1: Total Inflation | E1: Average | H1: source: https://m.the-numbers.com/market/
D2: Adjusted Box Office | E2: Ticket Price
A3: 2025 | B3: 766303564 | C3: 8666893310 | D3: 8666893310 | E3: 11.31
A4: 2024 | B4: 760482781 | C4: 8601060254 | D4: 8601060254 | E4: 11.31
A5: 2023 | B5: 819306691 | C5: 8963217610 | D5: 9266358669 | E5: 10.94
A6: 2022 | B6: 702373460 | C6: 7395994572 | D6: 7943843838 | E6: 10.53
A7: 2021 | B7: 444250543 | C7: 4518029580 | D7: 5024473637 | E7: 10.17
A8: 2020 | B8: 219986842 | C8: 2019481070 | D8: 2488051184 | E8: 9.18
A9: 2019 | B9: 1225563974 | C9: 11226168620 | D9: 13861128548 | E9: 9.16
A10: 2018 | B10: 1311558716 | C10: 11948302425 | D10: 14833727968 | E10: 9.11
A11: 2017 | B11: 1225762392 | C11: 10995091460 | D11: 13863372665 | E11: 8.97
A12: 2016 | B12: 1302610878 | C12: 11267792299 | D12: 14732529022 | E12: 8.65
A13: 2015 | B13: 1336743967 | C13: 11268754656 | D13: 15118574269 | E13: 8.43
A14: 2014 | B14: 1257327489 | C14: 10272368746 | D14: 14220373900 | E14: 8.17
... A33: 1995 | B33: 1221788544 | C33: 5314780870 | D33: 13818428426 | E33: 4.35

Sheet HHI
A1: Domestic Office | B1: In Billions | C1: Market Share | D1: HHI Delta | G1: Source: | H1: https://www.boxofficemojo.com/article/ed2573272068/
A2: Disney | B2: 3.092 | C2: =100*B2/(combined!C10/10^9) -> 25.878153 | D2: =(C2+C3)^2 - SUMSQ(C2:C3) -> 467.8222
A3: 20th Century Fox | B3: 1.08 | C3: =100*B3/(combined!$C$10/10^9) -> 9.0389409
A4: Warner Bros | B4: 1.94 | C4: =100*B4/(combined!$C$10/10^9) -> 16.236616
A5: Sony | B5: 1.24 | C5: =100*B5/(combined!$C$10/10^9) -> 10.378043
A6: Universal | B6: 1.96 | C6: =100*B6/(combined!$C$10/10^9) -> 16.404004
A7: Paramount | B7: 0.757 | C7: =100*B7/(combined!$C$10/10^9) -> 6.3356281
A9: Remaining Total Share | B9: =100-sum(C2:C7) -> 15.728614
A10: Remaining Max Individual Firm Share | B10: =min(C2:C7) -> 6.3356281
A11: Max Remaining Player | B11: =B9/B10 -> 2.482566
A13: Pre-merger HHI | B13: =SUMSQ(C2:C7) + B11*(B10^2) -> 1531.5949
A14: Post-merger HHI | B14: =SUMSQ(sum(C2:C3),C4:C7) + B11*(B10^2) -> 1999.4171
A15: HHI Delta | B15: =B14-B13 -> 467.8222

Sheet quarterly
A1: Year | B1: Cumulative Gross | C1: %± LY | D1: Releases | E1: Average | F1: #1 Release | G1: Gross | H1: % of Total | I1: Quarter
A2: 2025 | B2: 1423441460 | C2: -0.116 | D2: 216 | E2: 6590006 | F2: Captain America: Brave New World | G2: 196988959 | H2: 0.138 | I2: Q1
A3: 2024 | B3: 1609310109 | C3: -0.066 | D3: 215 | E3: 7485163 | F3: Dune: Part Two | G3: 252642707 | H3: 0.157 | I3: Q1
A4: 2023 | B4: 1722455494 | C4: =+28.1% -> 0.281 | D4: 187 | E4: 9210991 | F4: Avatar: The Way of Water | G4: 280147218 | H4: 0.163 | I4: Q1
A5: 2022 | B5: 1345032667 | C5: =+468.7% -> 4.687 | D5: 135 | E5: 9963204 | F5: The Batman | G5: 338200421 | H5: 0.251 | I5: Q1
A6: 2021 | B6: 236495603 | C6: -0.868 | D6: 111 | E6: 2130591 | F6: Tom & Jerry | G6: 37900149 | H6: 0.16 | I6: Q1
A7: 2020 | B7: 1789173905 | C7: -0.254 | D7: 246 | E7: 7273064 | F7: Bad Boys for Life | G7: 204417855 | H7: 0.114 | I7: Q1
A8: 2019 | B8: 2400027437 | C8: -0.16 | D8: 302 | E8: 7947110 | F8: Captain Marvel | G8: 353970079 | H8: 0.148 | I8: Q1
A9: 2018 | B9: 2858379432 | C9: -0.018 | D9: 321 | E9: 8904608 | F9: Black Panther | G9: 647827473 | H9: 0.227 | I9: Q1
A10: 2017 | B10: 2912280871 | C10: =+4.6% -> 0.046 | D10: 281 | E10: 10363988 | F10: Beauty and the Beast | G10: 360756693 | H10: 0.124 | I10: Q1
A11: 2016 | B11: 2784471480 | C11: =+12.5% -> 0.125 | D11: 263 | E11: 10587344 | F11: Deadpool | G11: 351608934 | H11: 0.126 | I11: Q1
A12: 2015 | B12: 2474840407 | C12: =+3.1% -> 0.031 | D12: 287 | E12: 8623137 | F12: American Sniper | G12: 344257525 | H12: 0.139 | I12: Q1
A13: 2014 | B13: 2399896607 | C13: =+5.6% -> 0.056 | D13: 302 | E13: 7946677 | F13: The Lego Movie | G13: 248466064 | H13: 0.104 | I13: Q1
A14: 2013 | B14: 2272778134 | C14: -0.124 | D14: 300 | E14: 7575927 | F14: Oz the Great and Powerful | G14: 198374716 | H14: 0.087 | I14: Q1
A15: 2012 | B15: 2593311679 | C15: =+23.8% -> 0.238 | D15: 288 | E15: 9004554 | F15: The Hunger Games | G15: 233324271 | H15: 0.09 | I15: Q1
A16: 2011 | B16: 2094029056 | C16: -0.209 | D16: 254 | E16: 8244208 | F16: The King's Speech | G16: 117779109 | H16: 0.056 | I16: Q1
A17: 2010 | B17: 2647418567 | C17: =+9% -> 0.09 | D17: 230 | E17: 11510515 | F17: Avatar | G17: 457515793 | H17: 0.173 | I17: Q1
A18: 2009 | B18: 2429351550 | C18: =+9.6% -> 0.096 | D18: 231 | E18: 10516673 | F18: Paul Blart: Mall Cop | G18: 142641708 | H18: 0.059 | I18: Q1
A19: 2008 | B19: 2216936112 | C19: =+2.6% -> 0.026 | D19: 273 | E19: 8120645 | F19: Horton Hears a Who! | G19: 118763428 | H19: 0.054 | I19: Q1
A20: 2007 | B20: 2161093052 | C20: =+6.9% -> 0.069 | D20: 274 | E20: 7887200 | F20: 300 | G20: 176488891 | H20: 0.082 | I20: Q1
A21: 2006 | B21: 2021028188 | C21: <0.1% | D21: 278 | E21: 7269885 | F21: The Pink Panther | G21: 81398292 | H21: 0.04 | I21: Q1
A22: 2005 | B22: 2019460461 | C22: -0.045 | D22: 241 | E22: 8379503 | F22: Hitch | G22: 168359864 | H22: 0.083 | I22: Q1
A23: 2004 | B23: 2114906060 | C23: =+6% -> 0.06 | D23: 265 | E23: 7980777 | F23: The Passion of the Christ | G23: 318972677 | H23: 0.151 | I23: Q1
A24: 2003 | B24: 1995420606 | C24: -0.045 | D24: 269 | E24: 7417920 | F24: Chicago | G24: 142019118 | H24: 0.071 | I24: Q1
A25: 2002 | B25: 2089641421 | C25: =+20.2% -> 0.202 | D25: 146 | E25: 14312612 | F25: A Beautiful Mind | G25: 144967885 | H25: 0.069 | I25: Q1
A26: 2001 | B26: 1737935031 | C26: =+8.7% -> 0.087 | D26: 145 | E26: 11985758 | F26: Hannibal | G26: 161288587 | H26: 0.093 | I26: Q1
A27: 2000 | B27: 1599313548 | C27: =+7.1% -> 0.071 | D27: 155 | E27: 10318151 | F27: Scream 3 | G27: 86680240 | H27: 0.054 | I27: Q1
A28: 1999 | B28: 1493520001 | C28: -0.058 | D28: 145 | E28: 10300137 | F28: Patch Adams | G28: 86964105 | H28: 0.058 | I28: Q1
A29: 1998 | B29: 1584603253 | C29: =+5.4% -> 0.054 | D29: 103 | E29: 15384497 | F29: Titanic | G29: 404465186 | H29: 0.255 | I29: Q1
A30: 1997 | B30: 1503346036 | C30: =+14.5% -> 0.145 | D30: 102 | E30: 14738686 | F30: Star Wars: Episode IV - A New Hope1997 Special Edition | G30: 135869744 | H30: 0.09 | I30: Q1
A31: 1996 | B31: 1312853239 | C31: =+27.2% -> 0.272 | D31: 100 | E31: 13128532 | F31: Mr. Holland's Opus | G31: 73596614 | H31: 0.056 | I31: Q1
A32: 1995 | B32: 1031958910 | C32: -0.054 | D32: 90 | E32: 11466210 | F32: Dumb and Dumber | G32: 70423183 | H32: 0.068 | I32: Q1
A33: 1994 | B33: 1090547186 | C33: =+5.9% -> 0.059 | D33: 80 | E33: 13631839 | F33: Mrs. Doubtfire | G33: 99557666 | H33: 0.091 | I33: Q1
A34: 1993 | B34: 1029975681 | C34: -0.049 | D34: 79 | E34: 13037666 | F34: Aladdin | G34: 96495266 | H34: 0.094 | I34: Q1
A35: 1992 | B35: 1082569421 | C35: -0.074 | D35: 80 | E35: 13532117 | F35: Wayne's World | G35: 86774633 | H35: 0.08 | I35: Q1
A36: 1991 | B36: 1169228320 | C36: =+27.1% -> 0.271 | D36: 78 | E36: 14990106 | F36: Home Alone | G36: 112371586 | H36: 0.096 | I36: Q1
A37: 1990 | B37: 920096405 | C37: =+8.4% -> 0.084 | D37: 74 | E37: 12433735 | F37: Driving Miss Daisy | G37: 77533890 | H37: 0.084 | I37: Q1
A38: 1989 | B38: 848510689 | C38: =+5.4% -> 0.054 | D38: 76 | E38: 11164614 | F38: Rain Man | G38: 104595898 | H38: 0.123 | I38: Q1
A39: 1988 | B39: 805248043 | C39: =+7.8% -> 0.078 | D39: 69 | E39: 11670261 | F39: Good Morning, Vietnam | G39: 102142288 | H39: 0.127 | I39: Q1
A40: 1987 | B40: 747325153 | C40: =+1.6% -> 0.016 | D40: 64 | E40: 11676955 | F40: Platoon | G40: 96969476 | H40: 0.13 | I40: Q1
...
